<?xml version="1.0" ?>
<robot xmlns:xacro="http://www.ros.org/wiki/xacro" name="test_arm_name">
    <xacro:macro name="rizon4_robot" params="id">
    <!-- JOINTS-->
    <joint name="base_joint" type="fixed">
      <parent link="world"/>
      <child link="base_link" />
      <origin xyz="0.0 0.0 0.0" rpy="0.0 0.0 0.0"/>
    </joint>

    <joint name="joint1" type="revolute">
      <parent link="base_link"/>
      <child link="link1"/>
      <origin xyz="0.0 0.0 0.155" rpy="0 0 -3.1416"/>
      <axis xyz="0 0 1"/>
      <limit effort="123" lower="-2.7925" upper="2.7925" velocity="2.0944"/>
    </joint>

    <joint name="joint2" type="revolute">
      <parent link="link1"/>
      <child link="link2"/>
      <origin xyz="0.0 0.03 0.210" rpy="0 0 0"/>
      <axis xyz="0 1 0"/>
      <limit effort="123" lower="-2.2689" upper="2.2689" velocity="2.0944"/>
    </joint>

    <joint name="joint3" type="revolute">
      <parent link="link2"/>
      <child link="link3"/>
      <origin xyz="0.0 0.035 0.205" rpy="0 0 0"/>
      <axis xyz="0 0 1"/>
      <limit effort="64" lower="-2.9671" upper="2.9671" velocity="2.4435"/>
    </joint>

    <joint name="joint4" type="revolute">
      <parent link="link3"/>
      <child link="link4"/>
      <origin xyz="-0.02 -0.03 0.19" rpy="0 0 -3.1416"/>
      <axis xyz="0 1 0"/>
      <limit effort="64" lower="-1.8675" upper="2.6878" velocity="2.4435" />
    </joint>

    <joint name="joint5" type="revolute">
      <parent link="link4"/>
      <child link="link5"/>
      <origin xyz="-0.02 0.025 0.195" rpy="0 0 -3.1416"/>
      <axis xyz="0 0 1"/>
      <limit effort="39" lower="-2.9671" upper="2.9671" velocity="4.8869" />
    </joint>

    <joint name="joint6" type="revolute">
      <parent link="link5"/>
      <child link="link6"/>
      <origin xyz="0.0 0.03 0.19" rpy="0 0 0"/>
      <axis xyz="0 1 0"/>
      <limit effort="39" lower="-1.3963" upper="4.5379" velocity="4.8869" />
    </joint>

    <joint name="joint7" type="revolute">
      <parent link="link6"/>
      <child link="link7"/>
      <origin xyz="-0.055 0.070 0.11" rpy="0 -1.5708 0"/>
      <axis xyz="0 0 1"/>
      <limit effort="39" lower="-2.9671" upper="2.9671" velocity="4.8869" />
    </joint>

    <joint name="link7_to_flange" type="fixed">
      <parent link="link7"/>
      <child link="flange"/>
        <origin xyz="0.0 0.0 0.081" rpy="0 0 -3.1416"/>
    </joint>

    <!-- LINKS -->
    <link name="world">
    </link>

    <link name="base_link">
      <inertial>
        <mass value="3.7" />
        <origin rpy="0 0 0" xyz="0.0 -0.0 0.09" />
        <inertia ixx="0.02" ixy="0.0" ixz="0.0" iyy="0.02" iyz="0.0" izz="0.01" />
      </inertial>
      <visual>
        <origin xyz="0 0 0" rpy="0 0 0"/>
        <geometry>
          <mesh filename="package://visual_rviz/meshes/rizon4/visual/link0.obj" />
        </geometry>
        <material name="rizon_light_grey" />
      </visual>
      <collision>
        <origin xyz="0 0 0" rpy="0 0 0"/>
        <geometry>
          <mesh filename="package://visual_rviz/meshes/rizon4/collision/link0.stl" />
        </geometry>
      </collision>
    </link>

    <link name="link1">
      <inertial>
        <mass value="3.7" />
        <origin rpy="0 0 0" xyz="0.0 0.01 0.15" />
        <inertia ixx="0.03" ixy="0.0" ixz="0.0" iyy="0.03" iyz="0.0" izz="0.01" />
      </inertial>
      <visual>
        <origin xyz="0 0 0" rpy="0 0 0" />
        <geometry>
          <mesh filename="package://visual_rviz/meshes/rizon4/visual/link1.obj" />
        </geometry>
        <material name="rizon_light_grey" />
      </visual>
      <collision>
        <origin xyz="0 0 0" rpy="0 0 0" />
        <geometry>
          <mesh filename="package://visual_rviz/meshes/rizon4/collision/link1.stl" />
        </geometry>
      </collision>
    </link>

    <link name="link2">
      <inertial>
        <mass value="2.7" />
        <origin rpy="0 0 0" xyz="0.0 0.04 0.1" />
        <inertia ixx="0.02" ixy="0.0" ixz="0.0" iyy="0.02" iyz="-0.0" izz="0.0" />
      </inertial>
      <visual>
        <origin xyz="0 0 0" rpy="0 0 0"/>
        <geometry>
          <mesh filename="package://visual_rviz/meshes/rizon4/visual/link2.obj" />
        </geometry>
        <material name="rizon_light_grey" />
      </visual>
      <collision>
        <origin xyz="0 0 0" rpy="0 0 0"/>
        <geometry>
          <mesh filename="package://visual_rviz/meshes/rizon4/collision/link2.stl" />
        </geometry>
      </collision>
    </link>

    <link name="link3">
      <inertial>
        <mass value="2.4" />
        <origin rpy="0 0 0" xyz="-0.01 -0.0 0.13" />
        <inertia ixx="0.01" ixy="0.0" ixz="-0.0" iyy="0.01" iyz="-0.0" izz="0.0" />
      </inertial>
      <visual>
        <origin xyz="0 0 0" rpy="0 0 0" />
        <geometry>
          <mesh filename="package://visual_rviz/meshes/rizon4/visual/link3.obj" />
        </geometry>
        <material name="rizon_light_grey" />
      </visual>
      <collision>
        <origin xyz="0 0 0" rpy="0 0 0" />
        <geometry>
          <mesh filename="package://visual_rviz/meshes/rizon4/collision/link3.stl" />
        </geometry>
      </collision>
    </link>

    <link name="link4">
      <inertial>
        <mass value="2.4" />
        <origin rpy="0 0 0" xyz="-0.01 0.03 0.1" />
        <inertia ixx="0.02" ixy="0.0" ixz="-0.0" iyy="0.02" iyz="-0.0" izz="0.0" />
      </inertial>
      <visual>
        <origin xyz="0 0 0" rpy="0 0 0"/>
        <geometry>
          <mesh filename="package://visual_rviz/meshes/rizon4/visual/link4.obj" />
        </geometry>
        <material name="rizon_light_grey" />
      </visual>
      <collision>
        <origin xyz="0 0 0" rpy="0 0 0"/>
        <geometry>
          <mesh filename="package://visual_rviz/meshes/rizon4/collision/link4.stl" />
        </geometry>
      </collision>
    </link>

    <link name="link5">
      <inertial>
        <mass value="2.4" />
        <origin rpy="0 0 0" xyz="0.0 0.0 0.13" />
        <inertia ixx="0.01" ixy="0.0" ixz="0.0" iyy="0.01" iyz="0.0" izz="0.0" />
      </inertial>
      <visual>
        <origin xyz="0 0 0" rpy="0 0 0"/>
        <geometry>
          <mesh filename="package://visual_rviz/meshes/rizon4/visual/link5.obj" />
        </geometry>
        <material name="rizon_light_grey" />
      </visual>
      <collision>
        <origin xyz="0 0 0" rpy="0 0 0"/>
        <geometry>
          <mesh filename="package://visual_rviz/meshes/rizon4/collision/link5.stl" />
        </geometry>
      </collision>
    </link>

    <link name="link6">
      <inertial>
        <mass value="2.1" />
        <origin rpy="0 0 0" xyz="-0.01 0.06 0.07" />
        <inertia ixx="0.01" ixy="-0.0" ixz="-0.001" iyy="0.01" iyz="0.0" izz="0.0" />
      </inertial>
      <visual>
        <origin xyz="0 0 0" rpy="0 0 0"/>
        <geometry>
          <mesh filename="package://visual_rviz/meshes/rizon4/visual/link6.obj" />
        </geometry>
        <material name="rizon_light_grey" />
      </visual>
      <collision>
        <origin xyz="0 0 0" rpy="0 0 0"/>
        <geometry>
          <mesh filename="package://visual_rviz/meshes/rizon4/collision/link6.stl" />
        </geometry>
      </collision>
    </link>

    <link name="link7">
        <inertial>
          <mass value="0.8" />
          <origin rpy="0 0 0" xyz="0.0 0.0 0.03" />
          <inertia ixx="0.0" ixy="0.0" ixz="0.0" iyy="0.0" iyz="0.0" izz="0.0" />
        </inertial>
        <visual>
          <origin xyz="0 0 0" rpy="0 0 0"/>
          <geometry>
            <mesh filename="package://visual_rviz/meshes/rizon4/visual/link7.obj" />
          </geometry>
          <material name="rizon_light_grey" />
        </visual>
        <collision>
          <origin xyz="0 0 0" rpy="0 0 0"/>
          <geometry>
            <mesh filename="package://visual_rviz/meshes/rizon4/collision/link7.stl" />
          </geometry>
        </collision>
    </link>

    <link name="flange"/>

    </xacro:macro>
</robot>

<xacro:rizon4_robot id="1"/>
